Workbook

Sheet Sheet1
B1: 3SI PTE. LTD.
B3: Leave History Report (Individual)
AM5: ABOOL FEDEBRIC MORIL
A6: Period From: 01-01-2025 To: 09-12-2025 | AM6: ALI MD ROMJAN
B7: Date : | C7: 09-12-2025 22:48:06 | AI7: Page : 1 of 128 | AM7: ALI MUSLIH BIN MOHAMED AFANDI
AM8: Aaron Rajadurai
AM9: FAITH JR. NEGAPATAN
AM10: GIRIDHARI RAMAMOORTHY
B11: Emp Code: 07001 Employee: R G S MURUKAN Leave Calculation Date: 01-10-2024 | AM11: GOVINDARAJU ANBALAGAN
AM12: HAQ AMINUL
A13: S No. | D13: Leave Date | J13: Day | N13: Remarks | Y13: Day / Hr | AF13: ML Claim Amt | AM13: HOSSAIN ABIR
AM14: JUSTINDRAN Y
AM15: Joe
AM16: KANNAN SURYAPRAKASH
B17: Leave Type: | H17: AL - ANNUAL LEAVE | AM17: KARUNAKARAN PERIYASAMY
AM18: KATHIRVEL RAMASAMY
AM19: KISHANRAJ PANNIR SELVAM
B20: 1 | D20: 02-01-2025 | J20: Thursday | Y20: 1.00 day | AM20: Koori selvam
AM21: LAVANIAH PUNNIYAMUTHY
B22: 2 | D22: 03-01-2025 | J22: Friday | Y22: 1.00 day | AM22: LOGESH A/L VEJAYAKUMURAN
AM23: MALAIKKOLUNDHU KUMARAVEL
B24: 3 | D24: 17-01-2025 | J24: Friday | Y24: 1.00 day | AM24: MANICKAN JAMUNA RANI
AM25: MARTIN NG SOO LEONG
B26: 4 | D26: 20-01-2025 | J26: Monday | Y26: 1.00 day | AM26: MIAH RASEL
AM27: MOHAMED ALAUDEEN MOHAMED ASLAM
B28: 5 | D28: 21-01-2025 | J28: Tuesday | Y28: 1.00 day | AM28: MOHAMMAD BILLAL
AM29: MOHAMMAD ERYAN SHAH BIN SAMSUDIN
B30: 6 | D30: 22-01-2025 | J30: Wednesday | Y30: 1.00 day | AM30: MOLLA FIROZ
AM31: MOSTAFIZUR RAHMAN
B32: 7 | D32: 23-01-2025 | J32: Thursday | Y32: 1.00 day | AM32: MUHAMMAD DANISH BIN YUSRI
AM33: MUHAMMAD HAQQ ARSHAQ MUHAMMAD NUR HAZLI
B34: 8 | D34: 24-01-2025 | J34: Friday | Y34: 1.00 day | AM34: MURUGAN SATHISHKUMAR
AM35: MUTHALIAPPAN KAILASANATHAN
B36: 9 | D36: 27-01-2025 | J36: Monday | Y36: 1.00 day | AM36: MUTHALIAPPAN KAILASANATHAN
AM37: MUTHUSAMY RAGAVAN
B38: 10 | D38: 28-01-2025 | J38: Tuesday | Y38: 1.00 day | AM38: Mustaq
AM39: NAVENH PATMANATHAN MOHAN RAJ
B40: 11 | D40: 31-01-2025 | J40: Friday | Y40: 1.00 day | AM40: NIRHUMALAN GANGAN
AM41: Nexa User
B42: 12 | D42: 11-02-2025 | J42: Tuesday | Y42: 1.00 day | AM42: OSMAN GONI MOHAMMAD
...

Sheet Data
A1: Employee Code | B1: Employee Name | C1: Leave Type | D1: From Date | E1: To Date | F1: Days | G1: Remarks | H1: Name?
A2: 7001 | B2: R G S MURUKAN | C2: AL | D2: 45689 | E2: 45689 | F2: 1 | H2: {=IFERROR( INDEX( Sheet1!$AM$5:$AM$62, MATCH( TRUE, ISNUMBER(SEARCH(LOWER(Sheet1!$AM$5:$AM$62), LOWER(B3))), 0 ) ), "NO MATCH" )} -> NO MATCH
A3: 7001 | B3: R G S MURUKAN | C3: AL | D3: 45717 | E3: 45717 | F3: 1 | H3: {=IFERROR( INDEX( Sheet1!$AM$5:$AM$62, MATCH( TRUE, ISNUMBER(SEARCH(LOWER(Sheet1!$AM$5:$AM$62), LOWER(B4))), 0 ) ), "NO MATCH" )} -> NO MATCH
A4: 7001 | B4: R G S MURUKAN | C4: AL | D4: 17-01-2025 | E4: 17-01-2025 | F4: 1 | H4: {=IFERROR( INDEX( Sheet1!$AM$5:$AM$62, MATCH( TRUE, ISNUMBER(SEARCH(LOWER(Sheet1!$AM$5:$AM$62), LOWER(B5))), 0 ) ), "NO MATCH" )} -> NO MATCH
A5: 7001 | B5: R G S MURUKAN | C5: AL | D5: 20-01-2025 | E5: 20-01-2025 | F5: 1 | H5: {=IFERROR( INDEX( Sheet1!$AM$5:$AM$62, MATCH( TRUE, ISNUMBER(SEARCH(LOWER(Sheet1!$AM$5:$AM$62), LOWER(B6))), 0 ) ), "NO MATCH" )} -> NO MATCH
A6: 7001 | B6: R G S MURUKAN | C6: AL | D6: 21-01-2025 | E6: 21-01-2025 | F6: 1 | H6: {=IFERROR( INDEX( Sheet1!$AM$5:$AM$62, MATCH( TRUE, ISNUMBER(SEARCH(LOWER(Sheet1!$AM$5:$AM$62), LOWER(B7))), 0 ) ), "NO MATCH" )} -> NO MATCH
A7: 7001 | B7: R G S MURUKAN | C7: AL | D7: 22-01-2025 | E7: 22-01-2025 | F7: 1 | H7: {=IFERROR( INDEX( Sheet1!$AM$5:$AM$62, MATCH( TRUE, ISNUMBER(SEARCH(LOWER(Sheet1!$AM$5:$AM$62), LOWER(B8))), 0 ) ), "NO MATCH" )} -> NO MATCH
A8: 7001 | B8: R G S MURUKAN | C8: AL | D8: 23-01-2025 | E8: 23-01-2025 | F8: 1 | H8: {=IFERROR( INDEX( Sheet1!$AM$5:$AM$62, MATCH( TRUE, ISNUMBER(SEARCH(LOWER(Sheet1!$AM$5:$AM$62), LOWER(B9))), 0 ) ), "NO MATCH" )} -> NO MATCH
A9: 7001 | B9: R G S MURUKAN | C9: AL | D9: 24-01-2025 | E9: 24-01-2025 | F9: 1 | H9: {=IFERROR( INDEX( Sheet1!$AM$5:$AM$62, MATCH( TRUE, ISNUMBER(SEARCH(LOWER(Sheet1!$AM$5:$AM$62), LOWER(B10))), 0 ) ), "NO MATCH" )} -> NO MATCH
A10: 7001 | B10: R G S MURUKAN | C10: AL | D10: 27-01-2025 | E10: 27-01-2025 | F10: 1 | H10: {=IFERROR( INDEX( Sheet1!$AM$5:$AM$62, MATCH( TRUE, ISNUMBER(SEARCH(LOWER(Sheet1!$AM$5:$AM$62), LOWER(B11))), 0 ) ), "NO MATCH" )} -> NO MATCH
A11: 7001 | B11: R G S MURUKAN | C11: AL | D11: 28-01-2025 | E11: 28-01-2025 | F11: 1 | H11: {=IFERROR( INDEX( Sheet1!$AM$5:$AM$62, MATCH( TRUE, ISNUMBER(SEARCH(LOWER(Sheet1!$AM$5:$AM$62), LOWER(B12))), 0 ) ), "NO MATCH" )} -> NO MATCH
A12: 7001 | B12: R G S MURUKAN | C12: AL | D12: 31-01-2025 | E12: 31-01-2025 | F12: 1 | H12: {=IFERROR( INDEX( Sheet1!$AM$5:$AM$62, MATCH( TRUE, ISNUMBER(SEARCH(LOWER(Sheet1!$AM$5:$AM$62), LOWER(B13))), 0 ) ), "NO MATCH" )} -> NO MATCH
A13: 7001 | B13: R G S MURUKAN | C13: AL | D13: 45963 | E13: 45963 | F13: 1 | H13: {=IFERROR( INDEX( Sheet1!$AM$5:$AM$62, MATCH( TRUE, ISNUMBER(SEARCH(LOWER(Sheet1!$AM$5:$AM$62), LOWER(B14))), 0 ) ), "NO MATCH" )} -> NO MATCH
A14: 7001 | B14: R G S MURUKAN | C14: AL | D14: 17-03-2025 | E14: 17-03-2025 | F14: 1 | H14: {=IFERROR( INDEX( Sheet1!$AM$5:$AM$62, MATCH( TRUE, ISNUMBER(SEARCH(LOWER(Sheet1!$AM$5:$AM$62), LOWER(B15))), 0 ) ), "NO MATCH" )} -> NO MATCH
A15: 7001 | B15: R G S MURUKAN | C15: AL | D15: 45965 | E15: 45965 | F15: 1 | H15: {=IFERROR( INDEX( Sheet1!$AM$5:$AM$62, MATCH( TRUE, ISNUMBER(SEARCH(LOWER(Sheet1!$AM$5:$AM$62), LOWER(B16))), 0 ) ), "NO MATCH" )} -> NO MATCH
A16: 7001 | B16: R G S MURUKAN | C16: AL | D16: 14-04-2025 | E16: 14-04-2025 | F16: 1 | H16: {=IFERROR( INDEX( Sheet1!$AM$5:$AM$62, MATCH( TRUE, ISNUMBER(SEARCH(LOWER(Sheet1!$AM$5:$AM$62), LOWER(B17))), 0 ) ), "NO MATCH" )} -> NO MATCH
A17: 7001 | B17: R G S MURUKAN | C17: ML | D17: 19-02-2025 | E17: 19-02-2025 | F17: 1 | H17: {=IFERROR( INDEX( Sheet1!$AM$5:$AM$62, MATCH( TRUE, ISNUMBER(SEARCH(LOWER(Sheet1!$AM$5:$AM$62), LOWER(B18))), 0 ) ), "NO MATCH" )} -> NO MATCH
A18: 7001 | B18: R G S MURUKAN | C18: ML | D18: 20-02-2025 | E18: 20-02-2025 | F18: 1 | H18: {=IFERROR( INDEX( Sheet1!$AM$5:$AM$62, MATCH( TRUE, ISNUMBER(SEARCH(LOWER(Sheet1!$AM$5:$AM$62), LOWER(B19))), 0 ) ), "NO MATCH" )} -> NO MATCH
A19: 7001 | B19: R G S MURUKAN | C19: ML | D19: 21-02-2025 | E19: 21-02-2025 | F19: 1 | H19: {=IFERROR( INDEX( Sheet1!$AM$5:$AM$62, MATCH( TRUE, ISNUMBER(SEARCH(LOWER(Sheet1!$AM$5:$AM$62), LOWER(B20))), 0 ) ), "NO MATCH" )} -> NO MATCH
A20: 7001 | B20: R G S MURUKAN | C20: ML | D20: 45661 | E20: 45661 | F20: 1 | H20: {=IFERROR( INDEX( Sheet1!$AM$5:$AM$62, MATCH( TRUE, ISNUMBER(SEARCH(LOWER(Sheet1!$AM$5:$AM$62), LOWER(B21))), 0 ) ), "NO MATCH" )} -> NO MATCH
A21: 7001 | B21: R G S MURUKAN | C21: ML | D21: 45692 | E21: 45692 | F21: 1 | H21: {=IFERROR( INDEX( Sheet1!$AM$5:$AM$62, MATCH( TRUE, ISNUMBER(SEARCH(LOWER(Sheet1!$AM$5:$AM$62), LOWER(B22))), 0 ) ), "NO MATCH" )} -> NO MATCH
A22: 7001 | B22: R G S MURUKAN | C22: OIL | D22: 45814 | E22: 45814 | F22: 1 | G22: Election day leave | H22: {=IFERROR( INDEX( Sheet1!$AM$5:$AM$62, MATCH( TRUE, ISNUMBER(SEARCH(LOWER(Sheet1!$AM$5:$AM$62), LOWER(B23))), 0 ) ), "NO MATCH" )} -> NO MATCH
A23: 7001 | B23: R G S MURUKAN | C23: UL | D23: 45813 | E23: 45813 | F23: 1 | G23: Unpaid Sabbatical leave | H23: {=IFERROR( INDEX( Sheet1!$AM$5:$AM$62, MATCH( TRUE, ISNUMBER(SEARCH(LOWER(Sheet1!$AM$5:$AM$62), LOWER(B24))), 0 ) ), "NO MATCH" )} -> NO MATCH
A24: 7001 | B24: R G S MURUKAN | C24: UL | D24: 45843 | E24: 45843 | F24: 1 | G24: Unpaid Sabbatical leave | H24: {=IFERROR( INDEX( Sheet1!$AM$5:$AM$62, MATCH( TRUE, ISNUMBER(SEARCH(LOWER(Sheet1!$AM$5:$AM$62), LOWER(B25))), 0 ) ), "NO MATCH" )} -> NO MATCH
A25: 7001 | B25: R G S MURUKAN | C25: UL | D25: 45874 | E25: 45874 | F25: 1 | G25: Unpaid Sabbatical leave | H25: {=IFERROR( INDEX( Sheet1!$AM$5:$AM$62, MATCH( TRUE, ISNUMBER(SEARCH(LOWER(Sheet1!$AM$5:$AM$62), LOWER(B26))), 0 ) ), "NO MATCH" )} -> NO MATCH
A26: 7001 | B26: R G S MURUKAN | C26: UL | D26: 45905 | E26: 45905 | F26: 1 | G26: Unpaid Sabbatical leave | H26: {=IFERROR( INDEX( Sheet1!$AM$5:$AM$62, MATCH( TRUE, ISNUMBER(SEARCH(LOWER(Sheet1!$AM$5:$AM$62), LOWER(B27))), 0 ) ), "NO MATCH" )} -> NO MATCH
A27: 7001 | B27: R G S MURUKAN | C27: UL | D27: 13-05-2025 | E27: 13-05-2025 | F27: 1 | G27: Unpaid Sabbatical leave | H27: {=IFERROR( INDEX( Sheet1!$AM$5:$AM$62, MATCH( TRUE, ISNUMBER(SEARCH(LOWER(Sheet1!$AM$5:$AM$62), LOWER(B28))), 0 ) ), "NO MATCH" )} -> NO MATCH
A28: 7001 | B28: R G S MURUKAN | C28: UL | D28: 14-05-2025 | E28: 14-05-2025 | F28: 1 | G28: Unpaid Sabbatical leave | H28: {=IFERROR( INDEX( Sheet1!$AM$5:$AM$62, MATCH( TRUE, ISNUMBER(SEARCH(LOWER(Sheet1!$AM$5:$AM$62), LOWER(B29))), 0 ) ), "NO MATCH" )} -> NO MATCH
A29: 7001 | B29: R G S MURUKAN | C29: UL | D29: 15-05-2025 | E29: 15-05-2025 | F29: 1 | G29: Unpaid Sabbatical leave | H29: {=IFERROR( INDEX( Sheet1!$AM$5:$AM$62, MATCH( TRUE, ISNUMBER(SEARCH(LOWER(Sheet1!$AM$5:$AM$62), LOWER(B30))), 0 ) ), "NO MATCH" )} -> NO MATCH
A30: 7001 | B30: R G S MURUKAN | C30: UL | D30: 16-05-2025 | E30: 16-05-2025 | F30: 1 | G30: Unpaid Sabbatical leave | H30: {=IFERROR( INDEX( Sheet1!$AM$5:$AM$62, MATCH( TRUE, ISNUMBER(SEARCH(LOWER(Sheet1!$AM$5:$AM$62), LOWER(B31))), 0 ) ), "NO MATCH" )} -> NO MATCH
A31: 7001 | B31: R G S MURUKAN | C31: UL | D31: 19-05-2025 | E31: 19-05-2025 | F31: 1 | G31: Unpaid Sabbatical leave | H31: {=IFERROR( INDEX( Sheet1!$AM$5:$AM$62, MATCH( TRUE, ISNUMBER(SEARCH(LOWER(Sheet1!$AM$5:$AM$62), LOWER(B32))), 0 ) ), "NO MATCH" )} -> NO MATCH
A32: 7001 | B32: R G S MURUKAN | C32: UL | D32: 20-05-2025 | E32: 20-05-2025 | F32: 1 | G32: Unpaid Sabbatical leave | H32: {=IFERROR( INDEX( Sheet1!$AM$5:$AM$62, MATCH( TRUE, ISNUMBER(SEARCH(LOWER(Sheet1!$AM$5:$AM$62), LOWER(B33))), 0 ) ), "NO MATCH" )} -> NO MATCH
A33: 7001 | B33: R G S MURUKAN | C33: UL | D33: 21-05-2025 | E33: 21-05-2025 | F33: 1 | G33: Unpaid Sabbatical leave | H33: {=IFERROR( INDEX( Sheet1!$AM$5:$AM$62, MATCH( TRUE, ISNUMBER(SEARCH(LOWER(Sheet1!$AM$5:$AM$62), LOWER(B34))), 0 ) ), "NO MATCH" )} -> NO MATCH
A34: 7001 | B34: R G S MURUKAN | C34: UL | D34: 22-05-2025 | E34: 22-05-2025 | F34: 1 | G34: Unpaid Sabbatical leave | H34: {=IFERROR( INDEX( Sheet1!$AM$5:$AM$62, MATCH( TRUE, ISNUMBER(SEARCH(LOWER(Sheet1!$AM$5:$AM$62), LOWER(B35))), 0 ) ), "NO MATCH" )} -> NO MATCH
A35: 7001 | B35: R G S MURUKAN | C35: UL | D35: 23-05-2025 | E35: 23-05-2025 | F35: 1 | G35: Unpaid Sabbatical leave | H35: {=IFERROR( INDEX( Sheet1!$AM$5:$AM$62, MATCH( TRUE, ISNUMBER(SEARCH(LOWER(Sheet1!$AM$5:$AM$62), LOWER(B36))), 0 ) ), "NO MATCH" )} -> NO MATCH
A36: 7001 | B36: R G S MURUKAN | C36: UL | D36: 26-05-2025 | E36: 26-05-2025 | F36: 1 | G36: Unpaid Sabbatical leave | H36: {=IFERROR( INDEX( Sheet1!$AM$5:$AM$62, MATCH( TRUE, ISNUMBER(SEARCH(LOWER(Sheet1!$AM$5:$AM$62), LOWER(B37))), 0 ) ), "NO MATCH" )} -> NO MATCH
A37: 7001 | B37: R G S MURUKAN | C37: UL | D37: 27-05-2025 | E37: 27-05-2025 | F37: 1 | G37: Unpaid Sabbatical leave | H37: {=IFERROR( INDEX( Sheet1!$AM$5:$AM$62, MATCH( TRUE, ISNUMBER(SEARCH(LOWER(Sheet1!$AM$5:$AM$62), LOWER(B38))), 0 ) ), "NO MATCH" )} -> NO MATCH
A38: 7001 | B38: R G S MURUKAN | C38: UL | D38: 28-05-2025 | E38: 28-05-2025 | F38: 1 | G38: Unpaid Sabbatical leave | H38: {=IFERROR( INDEX( Sheet1!$AM$5:$AM$62, MATCH( TRUE, ISNUMBER(SEARCH(LOWER(Sheet1!$AM$5:$AM$62), LOWER(B39))), 0 ) ), "NO MATCH" )} -> NO MATCH
... A40: 7001 | B40: R G S MURUKAN | C40: UL | D40: 30-05-2025 | E40: 30-05-2025 | F40: 1 | G40: Unpaid Sabbatical leave | H40: {=IFERROR( INDEX( Sheet1!$AM$5:$AM$62, MATCH( TRUE, ISNUMBER(SEARCH(LOWER(Sheet1!$AM$5:$AM$62), LOWER(B41))), 0 ) ), "NO MATCH" )} -> NO MATCH
A41: 7001 | B41: R G S MURUKAN | C41: UL | D41: 45694 | E41: 45694 | F41: 1 | G41: Unpaid Sabbatical leave | H41: {=IFERROR( INDEX( Sheet1!$AM$5:$AM$62, MATCH( TRUE, ISNUMBER(SEARCH(LOWER(Sheet1!$AM$5:$AM$62), LOWER(B42))), 0 ) ), "NO MATCH" )} -> NO MATCH
...

Sheet Employee
A1: Employee Code | B1: Employee Name | C1: Leave Type | D1: From Date | E1: To Date | F1: Days | G1: Remarks | H1: Name?
A2: 7001 | B2: R G S MURUKAN | C2: UL | D2: 45783 | E2: 45783 | F2: 1 | G2: Unpaid Sabbatical leave | H2: MOSTAFIZUR RAHMAN
A3: 14001 | B3: MOSTAFIZUR RAHMAN | C3: AL | D3: 30-06-2025 | E3: 30-06-2025 | F3: 1 | G3: I will be departing from Singapore on 29 June 2025 and will commence work on 14 July 2025 | H3: MOSTAFIZUR RAHMAN
A4: 14001 | B4: MOSTAFIZUR RAHMAN | C4: AL | D4: 45664 | E4: 45664 | F4: 1 | G4: I will be departing from Singapore on 29 June 2025 and will commence work on 14 July 2025 | H4: MOSTAFIZUR RAHMAN
A5: 14001 | B5: MOSTAFIZUR RAHMAN | C5: AL | D5: 45695 | E5: 45695 | F5: 1 | G5: I will be departing from Singapore on 29 June 2025 and will commence work on 14 July 2025 | H5: MOSTAFIZUR RAHMAN
A6: 14001 | B6: MOSTAFIZUR RAHMAN | C6: AL | D6: 45723 | E6: 45723 | F6: 1 | G6: I will be departing from Singapore on 29 June 2025 and will commence work on 14 July 2025 | H6: MOSTAFIZUR RAHMAN
A7: 14001 | B7: MOSTAFIZUR RAHMAN | C7: AL | D7: 45754 | E7: 45754 | F7: 1 | G7: I will be departing from Singapore on 29 June 2025 and will commence work on 14 July 2025 | H7: MOSTAFIZUR RAHMAN
A8: 14001 | B8: MOSTAFIZUR RAHMAN | C8: AL | D8: 45845 | E8: 45845 | F8: 1 | G8: I will be departing from Singapore on 29 June 2025 and will commence work on 14 July 2025 | H8: MOSTAFIZUR RAHMAN
A9: 14001 | B9: MOSTAFIZUR RAHMAN | C9: AL | D9: 45876 | E9: 45876 | F9: 1 | G9: I will be departing from Singapore on 29 June 2025 and will commence work on 14 July 2025 | H9: MOSTAFIZUR RAHMAN
A10: 14001 | B10: MOSTAFIZUR RAHMAN | C10: AL | D10: 45907 | E10: 45907 | F10: 1 | G10: I will be departing from Singapore on 29 June 2025 and will commence work on 14 July 2025 | H10: MOSTAFIZUR RAHMAN
A11: 14001 | B11: MOSTAFIZUR RAHMAN | C11: AL | D11: 45937 | E11: 45937 | F11: 1 | G11: I will be departing from Singapore on 29 June 2025 and will commence work on 14 July 2025 | H11: MOSTAFIZUR RAHMAN
A12: 14001 | B12: MOSTAFIZUR RAHMAN | C12: AL | D12: 45968 | E12: 45968 | F12: 1 | G12: I will be departing from Singapore on 29 June 2025 and will commence work on 14 July 2025 | H12: MOSTAFIZUR RAHMAN
A13: 14001 | B13: MOSTAFIZUR RAHMAN | C13: ML | D13: 45870 | E13: 45870 | F13: 1 | H13: MOSTAFIZUR RAHMAN
A14: 14001 | B14: MOSTAFIZUR RAHMAN | C14: ML | D14: 13-01-2025 | E14: 13-01-2025 | F14: 1 | H14: MOSTAFIZUR RAHMAN
A15: 14001 | B15: MOSTAFIZUR RAHMAN | C15: OIL | D15: 45879 | E15: 45879 | F15: 1 | G15: Short trip with family (Malaysia) [ Cancelled / Rejected Leave Re Applied ] | H15: MOSTAFIZUR RAHMAN
A16: 14001 | B16: MOSTAFIZUR RAHMAN | C16: OIL | D16: 45910 | E16: 45910 | F16: 1 | G16: Short trip with family (Malaysia) [ Cancelled / Rejected Leave Re Applied ] | H16: MOSTAFIZUR RAHMAN
A17: 14001 | B17: MOSTAFIZUR RAHMAN | C17: OIL | D17: 45940 | E17: 45940 | F17: 1 | G17: Short trip with family (Malaysia) [ Cancelled / Rejected Leave Re Applied ] | H17: VELLAIKKANNU VADIVELU
A18: 15001 | B18: VELLAIKKANNU VADIVELU | C18: AL | D18: 28-02-2025 | E18: 28-02-2025 | F18: 1 | H18: VELLAIKKANNU VADIVELU
A19: 15001 | B19: VELLAIKKANNU VADIVELU | C19: AL | D19: 45719 | E19: 45719 | F19: 1 | H19: VELLAIKKANNU VADIVELU
A20: 15001 | B20: VELLAIKKANNU VADIVELU | C20: AL | D20: 45750 | E20: 45750 | F20: 1 | H20: VELLAIKKANNU VADIVELU
A21: 15001 | B21: VELLAIKKANNU VADIVELU | C21: AL | D21: 45780 | E21: 45780 | F21: 1 | H21: VELLAIKKANNU VADIVELU
A22: 15001 | B22: VELLAIKKANNU VADIVELU | C22: AL | D22: 45811 | E22: 45811 | F22: 1 | H22: VELLAIKKANNU VADIVELU
A23: 15001 | B23: VELLAIKKANNU VADIVELU | C23: AL | D23: 45841 | E23: 45841 | F23: 1 | H23: VELLAIKKANNU VADIVELU
A24: 15001 | B24: VELLAIKKANNU VADIVELU | C24: AL | D24: 45872 | E24: 45872 | F24: 1 | H24: VELLAIKKANNU VADIVELU
A25: 15001 | B25: VELLAIKKANNU VADIVELU | C25: AL | D25: 45661 | E25: 45661 | F25: 1 | H25: VELLAIKKANNU VADIVELU
A26: 15001 | B26: VELLAIKKANNU VADIVELU | C26: ALSH | D26: 45660 | E26: 45660 | F26: 0.5 | H26: VELLAIKKANNU VADIVELU
A27: 15001 | B27: VELLAIKKANNU VADIVELU | C27: ML | D27: 23-07-2025 | E27: 23-07-2025 | F27: 1 | G27: fever | H27: VELLAIKKANNU VADIVELU
A28: 15001 | B28: VELLAIKKANNU VADIVELU | C28: ML | D28: 24-07-2025 | E28: 24-07-2025 | F28: 1 | G28: fever | H28: VELLAIKKANNU VADIVELU
A29: 15001 | B29: VELLAIKKANNU VADIVELU | C29: OIL | D29: 31-01-2025 | E29: 31-01-2025 | F29: 1 | H29: VELLAIKKANNU VADIVELU
A30: 15001 | B30: VELLAIKKANNU VADIVELU | C30: OIL | D30: 45659 | E30: 45659 | F30: 1 | H30: VELLAIKKANNU VADIVELU
A31: 15001 | B31: VELLAIKKANNU VADIVELU | C31: OIL | D31: 45718 | E31: 45718 | F31: 1 | H31: VELLAIKKANNU VADIVELU
A32: 15001 | B32: VELLAIKKANNU VADIVELU | C32: OIL | D32: 45749 | E32: 45749 | F32: 1 | H32: VELLAIKKANNU VADIVELU
A33: 15001 | B33: VELLAIKKANNU VADIVELU | C33: OIL | D33: 45779 | E33: 45779 | F33: 1 | H33: VELLAIKKANNU VADIVELU
A34: 15001 | B34: VELLAIKKANNU VADIVELU | C34: OIL | D34: 45810 | E34: 45810 | F34: 1 | H34: VELLAIKKANNU VADIVELU
A35: 15001 | B35: VELLAIKKANNU VADIVELU | C35: OIL | D35: 45840 | E35: 45840 | F35: 1 | H35: VELLAIKKANNU VADIVELU
A36: 15001 | B36: VELLAIKKANNU VADIVELU | C36: OIL | D36: 45871 | E36: 45871 | F36: 1 | H36: VELLAIKKANNU VADIVELU
A37: 15001 | B37: VELLAIKKANNU VADIVELU | C37: OIL | D37: 22-02-2025 | E37: 22-02-2025 | F37: 1 | H37: VELLAIKKANNU VADIVELU
A38: 15001 | B38: VELLAIKKANNU VADIVELU | C38: OIL | D38: 24-02-2025 | E38: 24-02-2025 | F38: 1 | H38: VELLAIKKANNU VADIVELU
A39: 15001 | B39: VELLAIKKANNU VADIVELU | C39: OIL | D39: 25-02-2025 | E39: 25-02-2025 | F39: 1 | H39: VELLAIKKANNU VADIVELU
A40: 15001 | B40: VELLAIKKANNU VADIVELU | C40: OIL | D40: 26-02-2025 | E40: 26-02-2025 | F40: 1 | H40: VELLAIKKANNU VADIVELU
...

Sheet Copy of Employee
A1: Employee Code | B1: Employee Name | C1: Leave Type | D1: From Date | E1: To Date | F1: Days | G1: Remarks
A2: 7001 | B2: R G S MURUKAN | C2: UL | D2: 45783 | E2: 45783 | F2: 1 | G2: Unpaid Sabbatical leave
A3: 14001 | B3: MOSTAFIZUR RAHMAN | C3: AL | D3: 30-06-2025 | E3: 30-06-2025 | F3: 1 | G3: I will be departing from Singapore on 29 June 2025 and will commence work on 14 July 2025
A4: 14001 | B4: MOSTAFIZUR RAHMAN | C4: AL | D4: 45664 | E4: 45664 | F4: 1 | G4: I will be departing from Singapore on 29 June 2025 and will commence work on 14 July 2025
A5: 14001 | B5: MOSTAFIZUR RAHMAN | C5: AL | D5: 45695 | E5: 45695 | F5: 1 | G5: I will be departing from Singapore on 29 June 2025 and will commence work on 14 July 2025
A6: 14001 | B6: MOSTAFIZUR RAHMAN | C6: AL | D6: 45723 | E6: 45723 | F6: 1 | G6: I will be departing from Singapore on 29 June 2025 and will commence work on 14 July 2025
A7: 14001 | B7: MOSTAFIZUR RAHMAN | C7: AL | D7: 45754 | E7: 45754 | F7: 1 | G7: I will be departing from Singapore on 29 June 2025 and will commence work on 14 July 2025
A8: 14001 | B8: MOSTAFIZUR RAHMAN | C8: AL | D8: 45845 | E8: 45845 | F8: 1 | G8: I will be departing from Singapore on 29 June 2025 and will commence work on 14 July 2025
A9: 14001 | B9: MOSTAFIZUR RAHMAN | C9: AL | D9: 45876 | E9: 45876 | F9: 1 | G9: I will be departing from Singapore on 29 June 2025 and will commence work on 14 July 2025
A10: 14001 | B10: MOSTAFIZUR RAHMAN | C10: AL | D10: 45907 | E10: 45907 | F10: 1 | G10: I will be departing from Singapore on 29 June 2025 and will commence work on 14 July 2025
A11: 14001 | B11: MOSTAFIZUR RAHMAN | C11: AL | D11: 45937 | E11: 45937 | F11: 1 | G11: I will be departing from Singapore on 29 June 2025 and will commence work on 14 July 2025
A12: 14001 | B12: MOSTAFIZUR RAHMAN | C12: AL | D12: 45968 | E12: 45968 | F12: 1 | G12: I will be departing from Singapore on 29 June 2025 and will commence work on 14 July 2025
A13: 14001 | B13: MOSTAFIZUR RAHMAN | C13: ML | D13: 45870 | E13: 45870 | F13: 1
A14: 14001 | B14: MOSTAFIZUR RAHMAN | C14: ML | D14: 13-01-2025 | E14: 13-01-2025 | F14: 1
A15: 14001 | B15: MOSTAFIZUR RAHMAN | C15: OIL | D15: 45879 | E15: 45879 | F15: 1 | G15: Short trip with family (Malaysia) [ Cancelled / Rejected Leave Re Applied ]
A16: 14001 | B16: MOSTAFIZUR RAHMAN | C16: OIL | D16: 45910 | E16: 45910 | F16: 1 | G16: Short trip with family (Malaysia) [ Cancelled / Rejected Leave Re Applied ]
A17: 14001 | B17: MOSTAFIZUR RAHMAN | C17: OIL | D17: 45940 | E17: 45940 | F17: 1 | G17: Short trip with family (Malaysia) [ Cancelled / Rejected Leave Re Applied ]
A18: 15001 | B18: VELLAIKKANNU VADIVELU | C18: AL | D18: 28-02-2025 | E18: 28-02-2025 | F18: 1
A19: 15001 | B19: VELLAIKKANNU VADIVELU | C19: AL | D19: 45719 | E19: 45719 | F19: 1
A20: 15001 | B20: VELLAIKKANNU VADIVELU | C20: AL | D20: 45750 | E20: 45750 | F20: 1
A21: 15001 | B21: VELLAIKKANNU VADIVELU | C21: AL | D21: 45780 | E21: 45780 | F21: 1
A22: 15001 | B22: VELLAIKKANNU VADIVELU | C22: AL | D22: 45811 | E22: 45811 | F22: 1
A23: 15001 | B23: VELLAIKKANNU VADIVELU | C23: AL | D23: 45841 | E23: 45841 | F23: 1
A24: 15001 | B24: VELLAIKKANNU VADIVELU | C24: AL | D24: 45872 | E24: 45872 | F24: 1
A25: 15001 | B25: VELLAIKKANNU VADIVELU | C25: AL | D25: 45661 | E25: 45661 | F25: 1
A26: 15001 | B26: VELLAIKKANNU VADIVELU | C26: ALSH | D26: 45660 | E26: 45660 | F26: 0.5
A27: 15001 | B27: VELLAIKKANNU VADIVELU | C27: ML | D27: 23-07-2025 | E27: 23-07-2025 | F27: 1 | G27: fever
A28: 15001 | B28: VELLAIKKANNU VADIVELU | C28: ML | D28: 24-07-2025 | E28: 24-07-2025 | F28: 1 | G28: fever
A29: 15001 | B29: VELLAIKKANNU VADIVELU | C29: OIL | D29: 31-01-2025 | E29: 31-01-2025 | F29: 1
A30: 15001 | B30: VELLAIKKANNU VADIVELU | C30: OIL | D30: 45659 | E30: 45659 | F30: 1
A31: 15001 | B31: VELLAIKKANNU VADIVELU | C31: OIL | D31: 45718 | E31: 45718 | F31: 1
A32: 15001 | B32: VELLAIKKANNU VADIVELU | C32: OIL | D32: 45749 | E32: 45749 | F32: 1
A33: 15001 | B33: VELLAIKKANNU VADIVELU | C33: OIL | D33: 45779 | E33: 45779 | F33: 1
A34: 15001 | B34: VELLAIKKANNU VADIVELU | C34: OIL | D34: 45810 | E34: 45810 | F34: 1
A35: 15001 | B35: VELLAIKKANNU VADIVELU | C35: OIL | D35: 45840 | E35: 45840 | F35: 1
A36: 15001 | B36: VELLAIKKANNU VADIVELU | C36: OIL | D36: 45871 | E36: 45871 | F36: 1
A37: 15001 | B37: VELLAIKKANNU VADIVELU | C37: OIL | D37: 22-02-2025 | E37: 22-02-2025 | F37: 1
A38: 15001 | B38: VELLAIKKANNU VADIVELU | C38: OIL | D38: 24-02-2025 | E38: 24-02-2025 | F38: 1
A39: 15001 | B39: VELLAIKKANNU VADIVELU | C39: OIL | D39: 25-02-2025 | E39: 25-02-2025 | F39: 1
A40: 15001 | B40: VELLAIKKANNU VADIVELU | C40: OIL | D40: 26-02-2025 | E40: 26-02-2025 | F40: 1
...

Sheet Copy of Data
A1: Employee Code | B1: Employee Name | C1: Leave Type | D1: From Date | E1: To Date | F1: Days | G1: Remarks | H1: Name?
A2: 7001 | B2: R G S MURUKAN | C2: AL | D2: 45689 | E2: 45689 | F2: 1 | H2: {=IFERROR( INDEX( Sheet1!$AM$5:$AM$62, MATCH( TRUE, ISNUMBER(SEARCH(LOWER(Sheet1!$AM$5:$AM$62), LOWER(B3))), 0 ) ), "NO MATCH" )} -> NO MATCH
A3: 7001 | B3: R G S MURUKAN | C3: AL | D3: 45717 | E3: 45717 | F3: 1 | H3: {=IFERROR( INDEX( Sheet1!$AM$5:$AM$62, MATCH( TRUE, ISNUMBER(SEARCH(LOWER(Sheet1!$AM$5:$AM$62), LOWER(B4))), 0 ) ), "NO MATCH" )} -> NO MATCH
A4: 7001 | B4: R G S MURUKAN | C4: AL | D4: 17-01-2025 | E4: 17-01-2025 | F4: 1 | H4: {=IFERROR( INDEX( Sheet1!$AM$5:$AM$62, MATCH( TRUE, ISNUMBER(SEARCH(LOWER(Sheet1!$AM$5:$AM$62), LOWER(B5))), 0 ) ), "NO MATCH" )} -> NO MATCH
A5: 7001 | B5: R G S MURUKAN | C5: AL | D5: 20-01-2025 | E5: 20-01-2025 | F5: 1 | H5: {=IFERROR( INDEX( Sheet1!$AM$5:$AM$62, MATCH( TRUE, ISNUMBER(SEARCH(LOWER(Sheet1!$AM$5:$AM$62), LOWER(B6))), 0 ) ), "NO MATCH" )} -> NO MATCH
A6: 7001 | B6: R G S MURUKAN | C6: AL | D6: 21-01-2025 | E6: 21-01-2025 | F6: 1 | H6: {=IFERROR( INDEX( Sheet1!$AM$5:$AM$62, MATCH( TRUE, ISNUMBER(SEARCH(LOWER(Sheet1!$AM$5:$AM$62), LOWER(B7))), 0 ) ), "NO MATCH" )} -> NO MATCH
A7: 7001 | B7: R G S MURUKAN | C7: AL | D7: 22-01-2025 | E7: 22-01-2025 | F7: 1 | H7: {=IFERROR( INDEX( Sheet1!$AM$5:$AM$62, MATCH( TRUE, ISNUMBER(SEARCH(LOWER(Sheet1!$AM$5:$AM$62), LOWER(B8))), 0 ) ), "NO MATCH" )} -> NO MATCH
A8: 7001 | B8: R G S MURUKAN | C8: AL | D8: 23-01-2025 | E8: 23-01-2025 | F8: 1 | H8: {=IFERROR( INDEX( Sheet1!$AM$5:$AM$62, MATCH( TRUE, ISNUMBER(SEARCH(LOWER(Sheet1!$AM$5:$AM$62), LOWER(B9))), 0 ) ), "NO MATCH" )} -> NO MATCH
A9: 7001 | B9: R G S MURUKAN | C9: AL | D9: 24-01-2025 | E9: 24-01-2025 | F9: 1 | H9: {=IFERROR( INDEX( Sheet1!$AM$5:$AM$62, MATCH( TRUE, ISNUMBER(SEARCH(LOWER(Sheet1!$AM$5:$AM$62), LOWER(B10))), 0 ) ), "NO MATCH" )} -> NO MATCH
A10: 7001 | B10: R G S MURUKAN | C10: AL | D10: 27-01-2025 | E10: 27-01-2025 | F10: 1 | H10: {=IFERROR( INDEX( Sheet1!$AM$5:$AM$62, MATCH( TRUE, ISNUMBER(SEARCH(LOWER(Sheet1!$AM$5:$AM$62), LOWER(B11))), 0 ) ), "NO MATCH" )} -> NO MATCH
A11: 7001 | B11: R G S MURUKAN | C11: AL | D11: 28-01-2025 | E11: 28-01-2025 | F11: 1 | H11: {=IFERROR( INDEX( Sheet1!$AM$5:$AM$62, MATCH( TRUE, ISNUMBER(SEARCH(LOWER(Sheet1!$AM$5:$AM$62), LOWER(B12))), 0 ) ), "NO MATCH" )} -> NO MATCH
A12: 7001 | B12: R G S MURUKAN | C12: AL | D12: 31-01-2025 | E12: 31-01-2025 | F12: 1 | H12: {=IFERROR( INDEX( Sheet1!$AM$5:$AM$62, MATCH( TRUE, ISNUMBER(SEARCH(LOWER(Sheet1!$AM$5:$AM$62), LOWER(B13))), 0 ) ), "NO MATCH" )} -> NO MATCH
A13: 7001 | B13: R G S MURUKAN | C13: AL | D13: 45963 | E13: 45963 | F13: 1 | H13: {=IFERROR( INDEX( Sheet1!$AM$5:$AM$62, MATCH( TRUE, ISNUMBER(SEARCH(LOWER(Sheet1!$AM$5:$AM$62), LOWER(B14))), 0 ) ), "NO MATCH" )} -> NO MATCH
A14: 7001 | B14: R G S MURUKAN | C14: AL | D14: 17-03-2025 | E14: 17-03-2025 | F14: 1 | H14: {=IFERROR( INDEX( Sheet1!$AM$5:$AM$62, MATCH( TRUE, ISNUMBER(SEARCH(LOWER(Sheet1!$AM$5:$AM$62), LOWER(B15))), 0 ) ), "NO MATCH" )} -> NO MATCH
A15: 7001 | B15: R G S MURUKAN | C15: AL | D15: 45965 | E15: 45965 | F15: 1 | H15: {=IFERROR( INDEX( Sheet1!$AM$5:$AM$62, MATCH( TRUE, ISNUMBER(SEARCH(LOWER(Sheet1!$AM$5:$AM$62), LOWER(B16))), 0 ) ), "NO MATCH" )} -> NO MATCH
A16: 7001 | B16: R G S MURUKAN | C16: AL | D16: 14-04-2025 | E16: 14-04-2025 | F16: 1 | H16: {=IFERROR( INDEX( Sheet1!$AM$5:$AM$62, MATCH( TRUE, ISNUMBER(SEARCH(LOWER(Sheet1!$AM$5:$AM$62), LOWER(B17))), 0 ) ), "NO MATCH" )} -> NO MATCH
A17: 7001 | B17: R G S MURUKAN | C17: ML | D17: 19-02-2025 | E17: 19-02-2025 | F17: 1 | H17: {=IFERROR( INDEX( Sheet1!$AM$5:$AM$62, MATCH( TRUE, ISNUMBER(SEARCH(LOWER(Sheet1!$AM$5:$AM$62), LOWER(B18))), 0 ) ), "NO MATCH" )} -> NO MATCH
A18: 7001 | B18: R G S MURUKAN | C18: ML | D18: 20-02-2025 | E18: 20-02-2025 | F18: 1 | H18: {=IFERROR( INDEX( Sheet1!$AM$5:$AM$62, MATCH( TRUE, ISNUMBER(SEARCH(LOWER(Sheet1!$AM$5:$AM$62), LOWER(B19))), 0 ) ), "NO MATCH" )} -> NO MATCH
A19: 7001 | B19: R G S MURUKAN | C19: ML | D19: 21-02-2025 | E19: 21-02-2025 | F19: 1 | H19: {=IFERROR( INDEX( Sheet1!$AM$5:$AM$62, MATCH( TRUE, ISNUMBER(SEARCH(LOWER(Sheet1!$AM$5:$AM$62), LOWER(B20))), 0 ) ), "NO MATCH" )} -> NO MATCH
A20: 7001 | B20: R G S MURUKAN | C20: ML | D20: 45661 | E20: 45661 | F20: 1 | H20: {=IFERROR( INDEX( Sheet1!$AM$5:$AM$62, MATCH( TRUE, ISNUMBER(SEARCH(LOWER(Sheet1!$AM$5:$AM$62), LOWER(B21))), 0 ) ), "NO MATCH" )} -> NO MATCH
A21: 7001 | B21: R G S MURUKAN | C21: ML | D21: 45692 | E21: 45692 | F21: 1 | H21: {=IFERROR( INDEX( Sheet1!$AM$5:$AM$62, MATCH( TRUE, ISNUMBER(SEARCH(LOWER(Sheet1!$AM$5:$AM$62), LOWER(B22))), 0 ) ), "NO MATCH" )} -> NO MATCH
A22: 7001 | B22: R G S MURUKAN | C22: OIL | D22: 45814 | E22: 45814 | F22: 1 | G22: Election day leave | H22: {=IFERROR( INDEX( Sheet1!$AM$5:$AM$62, MATCH( TRUE, ISNUMBER(SEARCH(LOWER(Sheet1!$AM$5:$AM$62), LOWER(B23))), 0 ) ), "NO MATCH" )} -> NO MATCH
A23: 7001 | B23: R G S MURUKAN | C23: UL | D23: 45813 | E23: 45813 | F23: 1 | G23: Unpaid Sabbatical leave | H23: {=IFERROR( INDEX( Sheet1!$AM$5:$AM$62, MATCH( TRUE, ISNUMBER(SEARCH(LOWER(Sheet1!$AM$5:$AM$62), LOWER(B24))), 0 ) ), "NO MATCH" )} -> NO MATCH
A24: 7001 | B24: R G S MURUKAN | C24: UL | D24: 45843 | E24: 45843 | F24: 1 | G24: Unpaid Sabbatical leave | H24: {=IFERROR( INDEX( Sheet1!$AM$5:$AM$62, MATCH( TRUE, ISNUMBER(SEARCH(LOWER(Sheet1!$AM$5:$AM$62), LOWER(B25))), 0 ) ), "NO MATCH" )} -> NO MATCH
A25: 7001 | B25: R G S MURUKAN | C25: UL | D25: 45874 | E25: 45874 | F25: 1 | G25: Unpaid Sabbatical leave | H25: {=IFERROR( INDEX( Sheet1!$AM$5:$AM$62, MATCH( TRUE, ISNUMBER(SEARCH(LOWER(Sheet1!$AM$5:$AM$62), LOWER(B26))), 0 ) ), "NO MATCH" )} -> NO MATCH
A26: 7001 | B26: R G S MURUKAN | C26: UL | D26: 45905 | E26: 45905 | F26: 1 | G26: Unpaid Sabbatical leave | H26: {=IFERROR( INDEX( Sheet1!$AM$5:$AM$62, MATCH( TRUE, ISNUMBER(SEARCH(LOWER(Sheet1!$AM$5:$AM$62), LOWER(B27))), 0 ) ), "NO MATCH" )} -> NO MATCH
A27: 7001 | B27: R G S MURUKAN | C27: UL | D27: 13-05-2025 | E27: 13-05-2025 | F27: 1 | G27: Unpaid Sabbatical leave | H27: {=IFERROR( INDEX( Sheet1!$AM$5:$AM$62, MATCH( TRUE, ISNUMBER(SEARCH(LOWER(Sheet1!$AM$5:$AM$62), LOWER(B28))), 0 ) ), "NO MATCH" )} -> NO MATCH
A28: 7001 | B28: R G S MURUKAN | C28: UL | D28: 14-05-2025 | E28: 14-05-2025 | F28: 1 | G28: Unpaid Sabbatical leave | H28: {=IFERROR( INDEX( Sheet1!$AM$5:$AM$62, MATCH( TRUE, ISNUMBER(SEARCH(LOWER(Sheet1!$AM$5:$AM$62), LOWER(B29))), 0 ) ), "NO MATCH" )} -> NO MATCH
A29: 7001 | B29: R G S MURUKAN | C29: UL | D29: 15-05-2025 | E29: 15-05-2025 | F29: 1 | G29: Unpaid Sabbatical leave | H29: {=IFERROR( INDEX( Sheet1!$AM$5:$AM$62, MATCH( TRUE, ISNUMBER(SEARCH(LOWER(Sheet1!$AM$5:$AM$62), LOWER(B30))), 0 ) ), "NO MATCH" )} -> NO MATCH
A30: 7001 | B30: R G S MURUKAN | C30: UL | D30: 16-05-2025 | E30: 16-05-2025 | F30: 1 | G30: Unpaid Sabbatical leave | H30: {=IFERROR( INDEX( Sheet1!$AM$5:$AM$62, MATCH( TRUE, ISNUMBER(SEARCH(LOWER(Sheet1!$AM$5:$AM$62), LOWER(B31))), 0 ) ), "NO MATCH" )} -> NO MATCH
A31: 7001 | B31: R G S MURUKAN | C31: UL | D31: 19-05-2025 | E31: 19-05-2025 | F31: 1 | G31: Unpaid Sabbatical leave | H31: {=IFERROR( INDEX( Sheet1!$AM$5:$AM$62, MATCH( TRUE, ISNUMBER(SEARCH(LOWER(Sheet1!$AM$5:$AM$62), LOWER(B32))), 0 ) ), "NO MATCH" )} -> NO MATCH
A32: 7001 | B32: R G S MURUKAN | C32: UL | D32: 20-05-2025 | E32: 20-05-2025 | F32: 1 | G32: Unpaid Sabbatical leave | H32: {=IFERROR( INDEX( Sheet1!$AM$5:$AM$62, MATCH( TRUE, ISNUMBER(SEARCH(LOWER(Sheet1!$AM$5:$AM$62), LOWER(B33))), 0 ) ), "NO MATCH" )} -> NO MATCH
A33: 7001 | B33: R G S MURUKAN | C33: UL | D33: 21-05-2025 | E33: 21-05-2025 | F33: 1 | G33: Unpaid Sabbatical leave | H33: {=IFERROR( INDEX( Sheet1!$AM$5:$AM$62, MATCH( TRUE, ISNUMBER(SEARCH(LOWER(Sheet1!$AM$5:$AM$62), LOWER(B34))), 0 ) ), "NO MATCH" )} -> NO MATCH
A34: 7001 | B34: R G S MURUKAN | C34: UL | D34: 22-05-2025 | E34: 22-05-2025 | F34: 1 | G34: Unpaid Sabbatical leave | H34: {=IFERROR( INDEX( Sheet1!$AM$5:$AM$62, MATCH( TRUE, ISNUMBER(SEARCH(LOWER(Sheet1!$AM$5:$AM$62), LOWER(B35))), 0 ) ), "NO MATCH" )} -> NO MATCH
A35: 7001 | B35: R G S MURUKAN | C35: UL | D35: 23-05-2025 | E35: 23-05-2025 | F35: 1 | G35: Unpaid Sabbatical leave | H35: {=IFERROR( INDEX( Sheet1!$AM$5:$AM$62, MATCH( TRUE, ISNUMBER(SEARCH(LOWER(Sheet1!$AM$5:$AM$62), LOWER(B36))), 0 ) ), "NO MATCH" )} -> NO MATCH
A36: 7001 | B36: R G S MURUKAN | C36: UL | D36: 26-05-2025 | E36: 26-05-2025 | F36: 1 | G36: Unpaid Sabbatical leave | H36: {=IFERROR( INDEX( Sheet1!$AM$5:$AM$62, MATCH( TRUE, ISNUMBER(SEARCH(LOWER(Sheet1!$AM$5:$AM$62), LOWER(B37))), 0 ) ), "NO MATCH" )} -> NO MATCH
A37: 7001 | B37: R G S MURUKAN | C37: UL | D37: 27-05-2025 | E37: 27-05-2025 | F37: 1 | G37: Unpaid Sabbatical leave | H37: {=IFERROR( INDEX( Sheet1!$AM$5:$AM$62, MATCH( TRUE, ISNUMBER(SEARCH(LOWER(Sheet1!$AM$5:$AM$62), LOWER(B38))), 0 ) ), "NO MATCH" )} -> NO MATCH
A38: 7001 | B38: R G S MURUKAN | C38: UL | D38: 28-05-2025 | E38: 28-05-2025 | F38: 1 | G38: Unpaid Sabbatical leave | H38: {=IFERROR( INDEX( Sheet1!$AM$5:$AM$62, MATCH( TRUE, ISNUMBER(SEARCH(LOWER(Sheet1!$AM$5:$AM$62), LOWER(B39))), 0 ) ), "NO MATCH" )} -> NO MATCH
... A40: 7001 | B40: R G S MURUKAN | C40: UL | D40: 30-05-2025 | E40: 30-05-2025 | F40: 1 | G40: Unpaid Sabbatical leave | H40: {=IFERROR( INDEX( Sheet1!$AM$5:$AM$62, MATCH( TRUE, ISNUMBER(SEARCH(LOWER(Sheet1!$AM$5:$AM$62), LOWER(B41))), 0 ) ), "NO MATCH" )} -> NO MATCH
A41: 7001 | B41: R G S MURUKAN | C41: UL | D41: 45694 | E41: 45694 | F41: 1 | G41: Unpaid Sabbatical leave | H41: {=IFERROR( INDEX( Sheet1!$AM$5:$AM$62, MATCH( TRUE, ISNUMBER(SEARCH(LOWER(Sheet1!$AM$5:$AM$62), LOWER(B42))), 0 ) ), "NO MATCH" )} -> NO MATCH
...

Sheet Dec Leave
B4: Prevoius MC Balance | C4: Nov MC | D4: Dec MC | E4: Eligible MC | G4: Previous Lve | H4: Dec lve eligiblr | I4: Nov Lve | J4: Dec Leave | K4: Eligible Lvs | M4: Date in Dec
A5: Selvam | B5: 12 | D5: 2 | E5: =B5-C5-D5 -> 10 | G5: 3 | H5: 1 | K5: =G5+H5-I5-J5 -> 4 | M5: 01, 12
A6: Ragavan | B6: 5 | D6: 4 | E6: =B6-C6-D6 -> 1 | G6: -1 | H6: 1 | K6: =G6+H6-I6-J6 -> 0 | M6: 1-3, 31
A7: Anba | B7: 3.5 | E7: =B7-C7-D7 -> 3.5 | G7: 7 | H7: 1 | I7: 3 | J7: 2 | K7: =G7+H7-I7-J7 -> 3 | M7: 3 & 5
A8: Sathishkumar Rama | E8: =B8-C8-D8 -> 0 | G8: 2 | H8: 1 | I8: 2 | J8: 1 | K8: =G8+H8-I8-J8 -> 0 | M8: 2
A9: Sathishkumar Rama | B9: 14 | D9: 4 | E9: =B9-C9-D9 -> 10 | H9: 1 | K9: =G9+H9-I9-J9 -> 1 | M9: 10, 15-16,27
A10: Rathnakumar | E10: =B10-C10-D10 -> 0 | G10: 3 | H10: 1 | I10: 1 | J10: 1 | K10: =G10+H10-I10-J10 -> 2 | M10: 3
A11: Nirmal | B11: 0 | D11: 1 | E11: =B11-C11-D11 -> -1 | G11: 1 | H11: 1 | I11: 1 | J11: 1 | K11: =G11+H11-I11-J11 -> 0 | M11: 8 | O11: UNPAID
A12: Kishanraj | B12: 0 | D12: 1 | E12: =B12-C12-D12 -> -1 | H12: 1 | K12: =G12+H12-I12-J12 -> 1 | M12: 8 | N12: No Document | O12: UNPAID
A13: Kishanraj | E13: =B13-C13-D13 -> 0 | G13: 2 | H13: 1 | I13: 2 | J13: 5 | K13: =G13+H13-I13-J13 -> -4 | M13: 1,5,10-12 | O13: UNPAID
A14: Osman Goni | B14: 9 | C14: 4 | D14: 1 | E14: =B14-C14-D14 -> 4 | H14: 1 | K14: =G14+H14-I14-J14 -> 1 | M14: 10
A15: Malai | B15: 13 | C15: 1 | D15: 1 | E15: =B15-C15-D15 -> 11 | H15: 1 | K15: =G15+H15-I15-J15 -> 1 | M15: 12
A16: Lavanya | B16: 5 | C16: 2 | D16: 1 | E16: =B16-C16-D16 -> 2 | H16: 1 | I16: 2 | K16: =G16+H16-I16-J16 -> -1 | M16: 12
A17: Shil sham sundar | E17: =B17-C17-D17 -> 0 | G17: 3 | H17: 1 | J17: 1 | K17: =G17+H17-I17-J17 -> 3 | M17: 15
A18: Vishnu Praveen | E18: =B18-C18-D18 -> 0 | G18: 1 | H18: 1 | J18: 1 | K18: =G18+H18-I18-J18 -> 1 | M18: 15
A19: Aminul Haq | B19: 6 | C19: 1 | D19: 1 | E19: =B19-C19-D19 -> 4 | H19: 1 | K19: =G19+H19-I19-J19 -> 1 | M19: 18
A20: Billan khan | B20: 7 | C20: 1 | D20: 3 | E20: =B20-C20-D20 -> 3 | H20: 1 | K20: =G20+H20-I20-J20 -> 1 | M20: 22-24
A21: Tulasi | B21: 13 | D21: 1 | E21: =B21-C21-D21 -> 12 | H21: 1 | K21: =G21+H21-I21-J21 -> 1 | M21: 30
A22: Kailasam | E22: =B22-C22-D22 -> 0 | H22: 1 | J22: 1 | K22: =G22+H22-I22-J22 -> 0 | M22: 31

Sheet Dec Leave (2)
B3: MC | G3: LEAVE
B4: Prevoius MC Balance | C4: Nov MC | D4: Dec MC | E4: Eligible MC | G4: Previous Lve | H4: Dec lve eligible | I4: Nov Lve | J4: Dec Leave | K4: Eligible Lvs | M4: Date in Dec
A5: Selvam | B5: 12 | D5: 2 | E5: =B5-C5-D5 -> 10 | G5: 3 | H5: 1 | K5: =G5+H5-I5-J5 -> 4 | M5: 01, 12
A6: Ragavan | B6: 5 | D6: 4 | E6: =B6-C6-D6 -> 1 | G6: -1 | H6: 1 | K6: =G6+H6-I6-J6 -> 0 | M6: 1-3, 31
A7: Anba | B7: 3.5 | E7: =B7-C7-D7 -> 3.5 | G7: 7 | H7: 1 | I7: 3 | J7: 2 | K7: =G7+H7-I7-J7 -> 3 | M7: 3 & 5
A8: Sathishkumar Rama | E8: =B8-C8-D8 -> 0 | G8: 2 | H8: 1 | I8: 2 | J8: 1 | K8: =G8+H8-I8-J8 -> 0 | M8: 2
A9: Sathishkumar Rama | B9: 14 | D9: 4 | E9: =B9-C9-D9 -> 10 | H9: 1 | K9: =G9+H9-I9-J9 -> 1 | M9: 10, 15-17,27
A10: Rathnakumar | E10: =B10-C10-D10 -> 0 | G10: 3 | H10: 1 | I10: 1 | J10: 1 | K10: =G10+H10-I10-J10 -> 2 | M10: 3
A11: Nirmal | B11: 0 | D11: 1 | E11: =B11-C11-D11 -> -1 | G11: 1 | H11: 1 | I11: 1 | J11: 1 | K11: =G11+H11-I11-J11 -> 0 | M11: 8 | O11: UNPAID
A12: Kishanraj | B12: 0 | D12: 1 | E12: =B12-C12-D12 -> -1 | H12: 1 | K12: =G12+H12-I12-J12 -> 1 | M12: 8 | N12: No Document | O12: UNPAID
A13: Kishanraj | E13: =B13-C13-D13 -> 0 | G13: 2 | H13: 1 | I13: 2 | J13: 5 | K13: =G13+H13-I13-J13 -> -4 | M13: 1,5,10-12 | O13: UNPAID
A14: Osman Goni | B14: 9 | C14: 4 | D14: 1 | E14: =B14-C14-D14 -> 4 | H14: 1 | K14: =G14+H14-I14-J14 -> 1 | M14: 10
A15: Malai | B15: 13 | C15: 1 | D15: 1 | E15: =B15-C15-D15 -> 11 | H15: 1 | K15: =G15+H15-I15-J15 -> 1 | M15: 12
A16: Lavanya | B16: 5 | C16: 2 | D16: 1 | E16: =B16-C16-D16 -> 2 | H16: 1 | I16: 2 | K16: =G16+H16-I16-J16 -> -1 | M16: 12 | N16: Unpaid
A17: Shil sham sundar | E17: =B17-C17-D17 -> 0 | G17: 3 | H17: 1 | J17: 1 | K17: =G17+H17-I17-J17 -> 3 | M17: 15
A18: Vishnu Praveen | E18: =B18-C18-D18 -> 0 | G18: 1 | H18: 1 | J18: 1 | K18: =G18+H18-I18-J18 -> 1 | M18: 15
A19: Aminul Haq | B19: 6 | C19: 1 | D19: 1 | E19: =B19-C19-D19 -> 4 | H19: 1 | K19: =G19+H19-I19-J19 -> 1 | M19: 18
A20: Billan khan | B20: 7 | C20: 1 | D20: 3 | E20: =B20-C20-D20 -> 3 | H20: 1 | K20: =G20+H20-I20-J20 -> 1 | M20: 22-24
A21: Tulasi | B21: 13 | D21: 1 | E21: =B21-C21-D21 -> 12 | H21: 1 | K21: =G21+H21-I21-J21 -> 1 | M21: 30
A22: Kailasam | E22: =B22-C22-D22 -> 0 | H22: 1 | J22: 1 | K22: =G22+H22-I22-J22 -> 0 | M22: 31
